Workbook

Sheet Methodology
A1: ROI Analysis — Methodology
A3: Two metrics are computed for every program x occupation combination (60 programs x 2 occupations = 120 rows):
A5: 1. PAYBACK PERIOD (years) — how long until the degree pays for itself
A6: Basic payback = Total tuition / Annual net salary
A7: Realistic payback = (Total tuition + Total living cost) / Annual net salary
A9: 2. CUMULATIVE ROI (%) — percentage return by year N, using the realistic total investment
A10: N-year ROI = ((N x Annual net salary) - (Total tuition + Total living cost)) / (Total tuition + Total living cost) x 100
A11: Computed at N = 5 years and N = 10 years post-graduation.
A13: SUMMARY STATISTIC: Since each country has 10 sampled programs, the Summary sheet reports the
A14: MEDIAN across those 10 programs, plus the 25th-75th percentile (IQR) to show spread — not just a
A15: single country-level average, which would hide how much results vary by specific program.
A17: KEY ASSUMPTIONS / LIMITATIONS
... A40: Salary and tax data: Graduate_outcomes.xlsx (per-country source citations in that file)

Sheet Tuition_Data
A1: Country | B1: Program | C1: University | D1: Total tuition (USD) | E1: Duration (months) | F1: Total living cost (USD) | G1: Total direct cost (USD)
A2: United States | B2: Business Analytics | C2: MIT | D2: 96884 | E2: 12 | F2: 54120 | G2: 151004
A3: United States | B3: Statistics & Data Science | C3: Stanford University | D3: 70900 | E3: 18 | F3: 90027 | G3: 160927
A4: United States | B4: Data Science | C4: Harvard University | D4: 101256 | E4: 16 | F4: 63245 | G4: 164501
A5: United States | B5: Data Science | C5: University of Pennsylvania | D5: 88250 | E5: 21 | F5: 63534 | G5: 151784
A6: United States | B6: Data Science & Applied Statistics | C6: Cornell University | D6: 73946 | E6: 12 | F6: 39829 | G6: 113775
A7: United States | B7: Statistics & Data Science | C7: Yale University | D7: 78600 | E7: 16 | F7: 58025 | G7: 136625
A8: United States | B8: Data Science | C8: Johns Hopkins University | D8: 103005 | E8: 16 | F8: 49061 | G8: 152066
A9: United States | B9: Statistics & Data Science | C9: University of California, Berkeley | D9: 55285 | E9: 10 | F9: 38472 | G9: 93757
A10: United States | B10: Applied Data Science | C10: University of Chicago | D10: 76608 | E10: 12 | F10: 46297 | G10: 122905
A11: United States | B11: Data Science | C11: Columbia University | D11: 84660 | E11: 16 | F11: 50037 | G11: 134697
A12: United Kingdom | B12: MSc Statistics (Data Science and Machine Learning) | C12: Imperial College London | D12: 53134 | E12: 12 | F12: 29446 | G12: 82580
A13: United Kingdom | B13: MSc in Statistical Science | C13: University of Oxford | D13: 58234 | E13: 12 | F13: 29078 | G13: 87312
... A61: Netherlands | B61: MSc Applied Mathematics — Mathematics of Data Science & AI | C61: University of Twente | D61: 49428 | E61: 24 | F61: 35834 | G61: 85263

Sheet Salary_Data
A1: Country | B1: Occupation | C1: Net_salary (USD)
A2: United States | B2: Data analyst | C2: 56670
A3: United States | B3: Data scientist | C3: 68785
A4: Canada | B4: Data analyst | C4: 43056
A5: Canada | B5: Data scientist | C5: 50856
A6: United Kingdom | B6: Data analyst | C6: 32523
A7: United Kingdom | B7: Data scientist | C7: 44249
A8: Australia | B8: Data analyst | C8: 45435
A9: Australia | B9: Data scientist | C9: 49280
A10: Germany | B10: Data analyst | C10: 41467
A11: Germany | B11: Data scientist | C11: 46310
A12: Netherlands | B12: Data analyst | C12: 42690
A13: Netherlands | B13: Data scientist | C13: 50320

Sheet ROI_Calculations
A1: Country | B1: Program | C1: University | D1: Occupation | E1: Total tuition (USD) | F1: Total direct cost (USD) | G1: Net salary (USD) | H1: Basic payback (years) | I1: Realistic payback (years) | J1: 5yr ROI (%) | K1: 10yr ROI (%)
A2: =Tuition_Data!A2 -> United States | B2: =Tuition_Data!B2 -> Business Analytics | C2: =Tuition_Data!C2 -> MIT | D2: Data analyst | E2: =Tuition_Data!D2 -> 96884 | F2: =Tuition_Data!G2 -> 151004 | G2: =SUMIFS(Salary_Data!$C$2:$C$13,Salary_Data!$A$2:$A$13,A2,Salary_Data!$B$2:$B$13,D2) -> 56670 | H2: =E2/G2 -> 1.7096171 | I2: =F2/G2 -> 2.6646197 | J2: =((5*G2-F2)/F2)*100 -> 87.644036 | K2: =((10*G2-F2)/F2)*100 -> 275.28807
A3: =Tuition_Data!A2 -> United States | B3: =Tuition_Data!B2 -> Business Analytics | C3: =Tuition_Data!C2 -> MIT | D3: Data scientist | E3: =Tuition_Data!D2 -> 96884 | F3: =Tuition_Data!G2 -> 151004 | G3: =SUMIFS(Salary_Data!$C$2:$C$13,Salary_Data!$A$2:$A$13,A3,Salary_Data!$B$2:$B$13,D3) -> 68785 | H3: =E3/G3 -> 1.4085048 | I3: =F3/G3 -> 2.1953042 | J3: =((5*G3-F3)/F3)*100 -> 127.75887 | K3: =((10*G3-F3)/F3)*100 -> 355.51773
A4: =Tuition_Data!A3 -> United States | B4: =Tuition_Data!B3 -> Statistics & Data Science | C4: =Tuition_Data!C3 -> Stanford University | D4: Data analyst | E4: =Tuition_Data!D3 -> 70900 | F4: =Tuition_Data!G3 -> 160927 | G4: =SUMIFS(Salary_Data!$C$2:$C$13,Salary_Data!$A$2:$A$13,A4,Salary_Data!$B$2:$B$13,D4) -> 56670 | H4: =E4/G4 -> 1.2511029 | I4: =F4/G4 -> 2.8397212 | J4: =((5*G4-F4)/F4)*100 -> 76.073623 | K4: =((10*G4-F4)/F4)*100 -> 252.14725
A5: =Tuition_Data!A3 -> United States | B5: =Tuition_Data!B3 -> Statistics & Data Science | C5: =Tuition_Data!C3 -> Stanford University | D5: Data scientist | E5: =Tuition_Data!D3 -> 70900 | F5: =Tuition_Data!G3 -> 160927 | G5: =SUMIFS(Salary_Data!$C$2:$C$13,Salary_Data!$A$2:$A$13,A5,Salary_Data!$B$2:$B$13,D5) -> 68785 | H5: =E5/G5 -> 1.030748 | I5: =F5/G5 -> 2.3395653 | J5: =((5*G5-F5)/F5)*100 -> 113.71491 | K5: =((10*G5-F5)/F5)*100 -> 327.42983
A6: =Tuition_Data!A4 -> United States | B6: =Tuition_Data!B4 -> Data Science | C6: =Tuition_Data!C4 -> Harvard University | D6: Data analyst | E6: =Tuition_Data!D4 -> 101256 | F6: =Tuition_Data!G4 -> 164501 | G6: =SUMIFS(Salary_Data!$C$2:$C$13,Salary_Data!$A$2:$A$13,A6,Salary_Data!$B$2:$B$13,D6) -> 56670 | H6: =E6/G6 -> 1.7867655 | I6: =F6/G6 -> 2.9027881 | J6: =((5*G6-F6)/F6)*100 -> 72.248193 | K6: =((10*G6-F6)/F6)*100 -> 244.49639
A7: =Tuition_Data!A4 -> United States | B7: =Tuition_Data!B4 -> Data Science | C7: =Tuition_Data!C4 -> Harvard University | D7: Data scientist | E7: =Tuition_Data!D4 -> 101256 | F7: =Tuition_Data!G4 -> 164501 | G7: =SUMIFS(Salary_Data!$C$2:$C$13,Salary_Data!$A$2:$A$13,A7,Salary_Data!$B$2:$B$13,D7) -> 68785 | H7: =E7/G7 -> 1.4720651 | I7: =F7/G7 -> 2.3915243 | J7: =((5*G7-F7)/F7)*100 -> 109.07168 | K7: =((10*G7-F7)/F7)*100 -> 318.14335
A8: =Tuition_Data!A5 -> United States | B8: =Tuition_Data!B5 -> Data Science | C8: =Tuition_Data!C5 -> University of Pennsylvania | D8: Data analyst | E8: =Tuition_Data!D5 -> 88250 | F8: =Tuition_Data!G5 -> 151784 | G8: =SUMIFS(Salary_Data!$C$2:$C$13,Salary_Data!$A$2:$A$13,A8,Salary_Data!$B$2:$B$13,D8) -> 56670 | H8: =E8/G8 -> 1.5572613 | I8: =F8/G8 -> 2.6783836 | J8: =((5*G8-F8)/F8)*100 -> 86.679755 | K8: =((10*G8-F8)/F8)*100 -> 273.35951
A9: =Tuition_Data!A5 -> United States | B9: =Tuition_Data!B5 -> Data Science | C9: =Tuition_Data!C5 -> University of Pennsylvania | D9: Data scientist | E9: =Tuition_Data!D5 -> 88250 | F9: =Tuition_Data!G5 -> 151784 | G9: =SUMIFS(Salary_Data!$C$2:$C$13,Salary_Data!$A$2:$A$13,A9,Salary_Data!$B$2:$B$13,D9) -> 68785 | H9: =E9/G9 -> 1.2829832 | I9: =F9/G9 -> 2.2066439 | J9: =((5*G9-F9)/F9)*100 -> 126.58844 | K9: =((10*G9-F9)/F9)*100 -> 353.17688
A10: =Tuition_Data!A6 -> United States | B10: =Tuition_Data!B6 -> Data Science & Applied Statistics | C10: =Tuition_Data!C6 -> Cornell University | D10: Data analyst | E10: =Tuition_Data!D6 -> 73946 | F10: =Tuition_Data!G6 -> 113775 | G10: =SUMIFS(Salary_Data!$C$2:$C$13,Salary_Data!$A$2:$A$13,A10,Salary_Data!$B$2:$B$13,D10) -> 56670 | H10: =E10/G10 -> 1.3048527 | I10: =F10/G10 -> 2.007676 | J10: =((5*G10-F10)/F10)*100 -> 149.04417 | K10: =((10*G10-F10)/F10)*100 -> 398.08833
A11: =Tuition_Data!A6 -> United States | B11: =Tuition_Data!B6 -> Data Science & Applied Statistics | C11: =Tuition_Data!C6 -> Cornell University | D11: Data scientist | E11: =Tuition_Data!D6 -> 73946 | F11: =Tuition_Data!G6 -> 113775 | G11: =SUMIFS(Salary_Data!$C$2:$C$13,Salary_Data!$A$2:$A$13,A11,Salary_Data!$B$2:$B$13,D11) -> 68785 | H11: =E11/G11 -> 1.0750309 | I11: =F11/G11 -> 1.654067 | J11: =((5*G11-F11)/F11)*100 -> 202.28521 | K11: =((10*G11-F11)/F11)*100 -> 504.57042
A12: =Tuition_Data!A7 -> United States | B12: =Tuition_Data!B7 -> Statistics & Data Science | C12: =Tuition_Data!C7 -> Yale University | D12: Data analyst | E12: =Tuition_Data!D7 -> 78600 | F12: =Tuition_Data!G7 -> 136625 | G12: =SUMIFS(Salary_Data!$C$2:$C$13,Salary_Data!$A$2:$A$13,A12,Salary_Data!$B$2:$B$13,D12) -> 56670 | H12: =E12/G12 -> 1.3869772 | I12: =F12/G12 -> 2.4108876 | J12: =((5*G12-F12)/F12)*100 -> 107.3925 | K12: =((10*G12-F12)/F12)*100 -> 314.785
A13: =Tuition_Data!A7 -> United States | B13: =Tuition_Data!B7 -> Statistics & Data Science | C13: =Tuition_Data!C7 -> Yale University | D13: Data scientist | E13: =Tuition_Data!D7 -> 78600 | F13: =Tuition_Data!G7 -> 136625 | G13: =SUMIFS(Salary_Data!$C$2:$C$13,Salary_Data!$A$2:$A$13,A13,Salary_Data!$B$2:$B$13,D13) -> 68785 | H13: =E13/G13 -> 1.142691 | I13: =F13/G13 -> 1.9862615 | J13: =((5*G13-F13)/F13)*100 -> 151.72919 | K13: =((10*G13-F13)/F13)*100 -> 403.45837
A14: =Tuition_Data!A8 -> United States | B14: =Tuition_Data!B8 -> Data Science | C14: =Tuition_Data!C8 -> Johns Hopkins University | D14: Data analyst | E14: =Tuition_Data!D8 -> 103005 | F14: =Tuition_Data!G8 -> 152066 | G14: =SUMIFS(Salary_Data!$C$2:$C$13,Salary_Data!$A$2:$A$13,A14,Salary_Data!$B$2:$B$13,D14) -> 56670 | H14: =E14/G14 -> 1.8176284 | I14: =F14/G14 -> 2.6833598 | J14: =((5*G14-F14)/F14)*100 -> 86.333566 | K14: =((10*G14-F14)/F14)*100 -> 272.66713
A15: =Tuition_Data!A8 -> United States | B15: =Tuition_Data!B8 -> Data Science | C15: =Tuition_Data!C8 -> Johns Hopkins University | D15: Data scientist | E15: =Tuition_Data!D8 -> 103005 | F15: =Tuition_Data!G8 -> 152066 | G15: =SUMIFS(Salary_Data!$C$2:$C$13,Salary_Data!$A$2:$A$13,A15,Salary_Data!$B$2:$B$13,D15) -> 68785 | H15: =E15/G15 -> 1.4974922 | I15: =F15/G15 -> 2.2107436 | J15: =((5*G15-F15)/F15)*100 -> 126.16824 | K15: =((10*G15-F15)/F15)*100 -> 352.33649
A16: =Tuition_Data!A9 -> United States | B16: =Tuition_Data!B9 -> Statistics & Data Science | C16: =Tuition_Data!C9 -> University of California, Berkeley | D16: Data analyst | E16: =Tuition_Data!D9 -> 55285 | F16: =Tuition_Data!G9 -> 93757 | G16: =SUMIFS(Salary_Data!$C$2:$C$13,Salary_Data!$A$2:$A$13,A16,Salary_Data!$B$2:$B$13,D16) -> 56670 | H16: =E16/G16 -> 0.97556026 | I16: =F16/G16 -> 1.654438 | J16: =((5*G16-F16)/F16)*100 -> 202.21743 | K16: =((10*G16-F16)/F16)*100 -> 504.43487
A17: =Tuition_Data!A9 -> United States | B17: =Tuition_Data!B9 -> Statistics & Data Science | C17: =Tuition_Data!C9 -> University of California, Berkeley | D17: Data scientist | E17: =Tuition_Data!D9 -> 55285 | F17: =Tuition_Data!G9 -> 93757 | G17: =SUMIFS(Salary_Data!$C$2:$C$13,Salary_Data!$A$2:$A$13,A17,Salary_Data!$B$2:$B$13,D17) -> 68785 | H17: =E17/G17 -> 0.80373628 | I17: =F17/G17 -> 1.3630443 | J17: =((5*G17-F17)/F17)*100 -> 266.82594 | K17: =((10*G17-F17)/F17)*100 -> 633.65189
A18: =Tuition_Data!A10 -> United States | B18: =Tuition_Data!B10 -> Applied Data Science | C18: =Tuition_Data!C10 -> University of Chicago | D18: Data analyst | E18: =Tuition_Data!D10 -> 76608 | F18: =Tuition_Data!G10 -> 122905 | G18: =SUMIFS(Salary_Data!$C$2:$C$13,Salary_Data!$A$2:$A$13,A18,Salary_Data!$B$2:$B$13,D18) -> 56670 | H18: =E18/G18 -> 1.3518264 | I18: =F18/G18 -> 2.1687842 | J18: =((5*G18-F18)/F18)*100 -> 130.54392 | K18: =((10*G18-F18)/F18)*100 -> 361.08783
A19: =Tuition_Data!A10 -> United States | B19: =Tuition_Data!B10 -> Applied Data Science | C19: =Tuition_Data!C10 -> University of Chicago | D19: Data scientist | E19: =Tuition_Data!D10 -> 76608 | F19: =Tuition_Data!G10 -> 122905 | G19: =SUMIFS(Salary_Data!$C$2:$C$13,Salary_Data!$A$2:$A$13,A19,Salary_Data!$B$2:$B$13,D19) -> 68785 | H19: =E19/G19 -> 1.1137312 | I19: =F19/G19 -> 1.7867994 | J19: =((5*G19-F19)/F19)*100 -> 179.82995 | K19: =((10*G19-F19)/F19)*100 -> 459.6599
A20: =Tuition_Data!A11 -> United States | B20: =Tuition_Data!B11 -> Data Science | C20: =Tuition_Data!C11 -> Columbia University | D20: Data analyst | E20: =Tuition_Data!D11 -> 84660 | F20: =Tuition_Data!G11 -> 134697 | G20: =SUMIFS(Salary_Data!$C$2:$C$13,Salary_Data!$A$2:$A$13,A20,Salary_Data!$B$2:$B$13,D20) -> 56670 | H20: =E20/G20 -> 1.4939121 | I20: =F20/G20 -> 2.3768661 | J20: =((5*G20-F20)/F20)*100 -> 110.36103 | K20: =((10*G20-F20)/F20)*100 -> 320.72207
A21: =Tuition_Data!A11 -> United States | B21: =Tuition_Data!B11 -> Data Science | C21: =Tuition_Data!C11 -> Columbia University | D21: Data scientist | E21: =Tuition_Data!D11 -> 84660 | F21: =Tuition_Data!G11 -> 134697 | G21: =SUMIFS(Salary_Data!$C$2:$C$13,Salary_Data!$A$2:$A$13,A21,Salary_Data!$B$2:$B$13,D21) -> 68785 | H21: =E21/G21 -> 1.2307916 | I21: =F21/G21 -> 1.9582322 | J21: =((5*G21-F21)/F21)*100 -> 155.33234 | K21: =((10*G21-F21)/F21)*100 -> 410.66468
A22: =Tuition_Data!A12 -> United Kingdom | B22: =Tuition_Data!B12 -> MSc Statistics (Data Science and Machine Learning) | C22: =Tuition_Data!C12 -> Imperial College London | D22: Data analyst | E22: =Tuition_Data!D12 -> 53134 | F22: =Tuition_Data!G12 -> 82580 | G22: =SUMIFS(Salary_Data!$C$2:$C$13,Salary_Data!$A$2:$A$13,A22,Salary_Data!$B$2:$B$13,D22) -> 32523 | H22: =E22/G22 -> 1.6337361 | I22: =F22/G22 -> 2.5391262 | J22: =((5*G22-F22)/F22)*100 -> 96.91814 | K22: =((10*G22-F22)/F22)*100 -> 293.83628
A23: =Tuition_Data!A12 -> United Kingdom | B23: =Tuition_Data!B12 -> MSc Statistics (Data Science and Machine Learning) | C23: =Tuition_Data!C12 -> Imperial College London | D23: Data scientist | E23: =Tuition_Data!D12 -> 53134 | F23: =Tuition_Data!G12 -> 82580 | G23: =SUMIFS(Salary_Data!$C$2:$C$13,Salary_Data!$A$2:$A$13,A23,Salary_Data!$B$2:$B$13,D23) -> 44249 | H23: =E23/G23 -> 1.2007955 | I23: =F23/G23 -> 1.8662569 | J23: =((5*G23-F23)/F23)*100 -> 167.91596 | K23: =((10*G23-F23)/F23)*100 -> 435.83192
A24: =Tuition_Data!A13 -> United Kingdom | B24: =Tuition_Data!B13 -> MSc in Statistical Science | C24: =Tuition_Data!C13 -> University of Oxford | D24: Data analyst | E24: =Tuition_Data!D13 -> 58234 | F24: =Tuition_Data!G13 -> 87312 | G24: =SUMIFS(Salary_Data!$C$2:$C$13,Salary_Data!$A$2:$A$13,A24,Salary_Data!$B$2:$B$13,D24) -> 32523 | H24: =E24/G24 -> 1.7905482 | I24: =F24/G24 -> 2.6846232 | J24: =((5*G24-F24)/F24)*100 -> 86.245877 | K24: =((10*G24-F24)/F24)*100 -> 272.49175
A25: =Tuition_Data!A13 -> United Kingdom | B25: =Tuition_Data!B13 -> MSc in Statistical Science | C25: =Tuition_Data!C13 -> University of Oxford | D25: Data scientist | E25: =Tuition_Data!D13 -> 58234 | F25: =Tuition_Data!G13 -> 87312 | G25: =SUMIFS(Salary_Data!$C$2:$C$13,Salary_Data!$A$2:$A$13,A25,Salary_Data!$B$2:$B$13,D25) -> 44249 | H25: =E25/G25 -> 1.3160523 | I25: =F25/G25 -> 1.9731971 | J25: =((5*G25-F25)/F25)*100 -> 153.39587 | K25: =((10*G25-F25)/F25)*100 -> 406.79174
A26: =Tuition_Data!A14 -> United Kingdom | B26: =Tuition_Data!B14 -> MPhil in Data Intensive Science | C26: =Tuition_Data!C14 -> University of Cambridge | D26: Data analyst | E26: =Tuition_Data!D14 -> 52383 | F26: =Tuition_Data!G14 -> 75283 | G26: =SUMIFS(Salary_Data!$C$2:$C$13,Salary_Data!$A$2:$A$13,A26,Salary_Data!$B$2:$B$13,D26) -> 32523 | H26: =E26/G26 -> 1.6106448 | I26: =F26/G26 -> 2.3147619 | J26: =((5*G26-F26)/F26)*100 -> 116.00494 | K26: =((10*G26-F26)/F26)*100 -> 332.00988
A27: =Tuition_Data!A14 -> United Kingdom | B27: =Tuition_Data!B14 -> MPhil in Data Intensive Science | C27: =Tuition_Data!C14 -> University of Cambridge | D27: Data scientist | E27: =Tuition_Data!D14 -> 52383 | F27: =Tuition_Data!G14 -> 75283 | G27: =SUMIFS(Salary_Data!$C$2:$C$13,Salary_Data!$A$2:$A$13,A27,Salary_Data!$B$2:$B$13,D27) -> 44249 | H27: =E27/G27 -> 1.1838234 | I27: =F27/G27 -> 1.7013492 | J27: =((5*G27-F27)/F27)*100 -> 193.88441 | K27: =((10*G27-F27)/F27)*100 -> 487.76882
A28: =Tuition_Data!A15 -> United Kingdom | B28: =Tuition_Data!B15 -> Data Science MSc | C28: =Tuition_Data!C15 -> UCL | D28: Data analyst | E28: =Tuition_Data!D15 -> 62189 | F28: =Tuition_Data!G15 -> 89856 | G28: =SUMIFS(Salary_Data!$C$2:$C$13,Salary_Data!$A$2:$A$13,A28,Salary_Data!$B$2:$B$13,D28) -> 32523 | H28: =E28/G28 -> 1.9121545 | I28: =F28/G28 -> 2.7628448 | J28: =((5*G28-F28)/F28)*100 -> 80.97289 | K28: =((10*G28-F28)/F28)*100 -> 261.94578
A29: =Tuition_Data!A15 -> United Kingdom | B29: =Tuition_Data!B15 -> Data Science MSc | C29: =Tuition_Data!C15 -> UCL | D29: Data scientist | E29: =Tuition_Data!D15 -> 62189 | F29: =Tuition_Data!G15 -> 89856 | G29: =SUMIFS(Salary_Data!$C$2:$C$13,Salary_Data!$A$2:$A$13,A29,Salary_Data!$B$2:$B$13,D29) -> 44249 | H29: =E29/G29 -> 1.4054329 | I29: =F29/G29 -> 2.03069 | J29: =((5*G29-F29)/F29)*100 -> 146.22173 | K29: =((10*G29-F29)/F29)*100 -> 392.44347
A30: =Tuition_Data!A16 -> United Kingdom | B30: =Tuition_Data!B16 -> Data Science MSc | C30: =Tuition_Data!C16 -> University of Edinburgh | D30: Data analyst | E30: =Tuition_Data!D16 -> 54465 | F30: =Tuition_Data!G16 -> 80140 | G30: =SUMIFS(Salary_Data!$C$2:$C$13,Salary_Data!$A$2:$A$13,A30,Salary_Data!$B$2:$B$13,D30) -> 32523 | H30: =E30/G30 -> 1.674661 | I30: =F30/G30 -> 2.4641023 | J30: =((5*G30-F30)/F30)*100 -> 102.91365 | K30: =((10*G30-F30)/F30)*100 -> 305.8273
A31: =Tuition_Data!A16 -> United Kingdom | B31: =Tuition_Data!B16 -> Data Science MSc | C31: =Tuition_Data!C16 -> University of Edinburgh | D31: Data scientist | E31: =Tuition_Data!D16 -> 54465 | F31: =Tuition_Data!G16 -> 80140 | G31: =SUMIFS(Salary_Data!$C$2:$C$13,Salary_Data!$A$2:$A$13,A31,Salary_Data!$B$2:$B$13,D31) -> 44249 | H31: =E31/G31 -> 1.2308753 | I31: =F31/G31 -> 1.8111144 | J31: =((5*G31-F31)/F31)*100 -> 176.07312 | K31: =((10*G31-F31)/F31)*100 -> 452.14624
A32: =Tuition_Data!A17 -> United Kingdom | B32: =Tuition_Data!B17 -> Data Science MSc | C32: =Tuition_Data!C17 -> King's College London | D32: Data analyst | E32: =Tuition_Data!D17 -> 53866 | F32: =Tuition_Data!G17 -> 83184 | G32: =SUMIFS(Salary_Data!$C$2:$C$13,Salary_Data!$A$2:$A$13,A32,Salary_Data!$B$2:$B$13,D32) -> 32523 | H32: =E32/G32 -> 1.6562433 | I32: =F32/G32 -> 2.5576976 | J32: =((5*G32-F32)/F32)*100 -> 95.488315 | K32: =((10*G32-F32)/F32)*100 -> 290.97663
A33: =Tuition_Data!A17 -> United Kingdom | B33: =Tuition_Data!B17 -> Data Science MSc | C33: =Tuition_Data!C17 -> King's College London | D33: Data scientist | E33: =Tuition_Data!D17 -> 53866 | F33: =Tuition_Data!G17 -> 83184 | G33: =SUMIFS(Salary_Data!$C$2:$C$13,Salary_Data!$A$2:$A$13,A33,Salary_Data!$B$2:$B$13,D33) -> 44249 | H33: =E33/G33 -> 1.2173382 | I33: =F33/G33 -> 1.8799069 | J33: =((5*G33-F33)/F33)*100 -> 165.97062 | K33: =((10*G33-F33)/F33)*100 -> 431.94124
A34: =Tuition_Data!A18 -> United Kingdom | B34: =Tuition_Data!B18 -> MSc Data Science (Computer Science Data Informatics) | C34: =Tuition_Data!C18 -> University of Manchester | D34: Data analyst | E34: =Tuition_Data!D18 -> 46875 | F34: =Tuition_Data!G18 -> 72129 | G34: =SUMIFS(Salary_Data!$C$2:$C$13,Salary_Data!$A$2:$A$13,A34,Salary_Data!$B$2:$B$13,D34) -> 32523 | H34: =E34/G34 -> 1.4412877 | I34: =F34/G34 -> 2.2177843 | J34: =((5*G34-F34)/F34)*100 -> 125.45023 | K34: =((10*G34-F34)/F34)*100 -> 350.90047
A35: =Tuition_Data!A18 -> United Kingdom | B35: =Tuition_Data!B18 -> MSc Data Science (Computer Science Data Informatics) | C35: =Tuition_Data!C18 -> University of Manchester | D35: Data scientist | E35: =Tuition_Data!D18 -> 46875 | F35: =Tuition_Data!G18 -> 72129 | G35: =SUMIFS(Salary_Data!$C$2:$C$13,Salary_Data!$A$2:$A$13,A35,Salary_Data!$B$2:$B$13,D35) -> 44249 | H35: =E35/G35 -> 1.059346 | I35: =F35/G35 -> 1.6300707 | J35: =((5*G35-F35)/F35)*100 -> 206.73516 | K35: =((10*G35-F35)/F35)*100 -> 513.47031
A36: =Tuition_Data!A19 -> United Kingdom | B36: =Tuition_Data!B19 -> MSc Data Science | C36: =Tuition_Data!C19 -> University of Bristol | D36: Data analyst | E36: =Tuition_Data!D19 -> 48606 | F36: =Tuition_Data!G19 -> 79394 | G36: =SUMIFS(Salary_Data!$C$2:$C$13,Salary_Data!$A$2:$A$13,A36,Salary_Data!$B$2:$B$13,D36) -> 32523 | H36: =E36/G36 -> 1.4945116 | I36: =F36/G36 -> 2.4411647 | J36: =((5*G36-F36)/F36)*100 -> 104.82026 | K36: =((10*G36-F36)/F36)*100 -> 309.64053
A37: =Tuition_Data!A19 -> United Kingdom | B37: =Tuition_Data!B19 -> MSc Data Science | C37: =Tuition_Data!C19 -> University of Bristol | D37: Data scientist | E37: =Tuition_Data!D19 -> 48606 | F37: =Tuition_Data!G19 -> 79394 | G37: =SUMIFS(Salary_Data!$C$2:$C$13,Salary_Data!$A$2:$A$13,A37,Salary_Data!$B$2:$B$13,D37) -> 44249 | H37: =E37/G37 -> 1.0984655 | I37: =F37/G37 -> 1.7942552 | J37: =((5*G37-F37)/F37)*100 -> 178.66715 | K37: =((10*G37-F37)/F37)*100 -> 457.33431
A38: =Tuition_Data!A20 -> United Kingdom | B38: =Tuition_Data!B20 -> MSc Data Science | C38: =Tuition_Data!C20 -> London School of Economics and Political Science (LSE) | D38: Data analyst | E38: =Tuition_Data!D20 -> 53134 | F38: =Tuition_Data!G20 -> 78936 | G38: =SUMIFS(Salary_Data!$C$2:$C$13,Salary_Data!$A$2:$A$13,A38,Salary_Data!$B$2:$B$13,D38) -> 32523 | H38: =E38/G38 -> 1.6337361 | I38: =F38/G38 -> 2.4270824 | J38: =((5*G38-F38)/F38)*100 -> 106.00867 | K38: =((10*G38-F38)/F38)*100 -> 312.01733
A39: =Tuition_Data!A20 -> United Kingdom | B39: =Tuition_Data!B20 -> MSc Data Science | C39: =Tuition_Data!C20 -> London School of Economics and Political Science (LSE) | D39: Data scientist | E39: =Tuition_Data!D20 -> 53134 | F39: =Tuition_Data!G20 -> 78936 | G39: =SUMIFS(Salary_Data!$C$2:$C$13,Salary_Data!$A$2:$A$13,A39,Salary_Data!$B$2:$B$13,D39) -> 44249 | H39: =E39/G39 -> 1.2007955 | I39: =F39/G39 -> 1.7839047 | J39: =((5*G39-F39)/F39)*100 -> 180.28403 | K39: =((10*G39-F39)/F39)*100 -> 460.56806
A40: =Tuition_Data!A21 -> United Kingdom | B40: =Tuition_Data!B21 -> Statistics with Data Science MSc | C40: =Tuition_Data!C21 -> University of Warwick | D40: Data analyst | E40: =Tuition_Data!D21 -> 49884 | F40: =Tuition_Data!G21 -> 69071 | G40: =SUMIFS(Salary_Data!$C$2:$C$13,Salary_Data!$A$2:$A$13,A40,Salary_Data!$B$2:$B$13,D40) -> 32523 | H40: =E40/G40 -> 1.5338068 | I40: =F40/G40 -> 2.1237586 | J40: =((5*G40-F40)/F40)*100 -> 135.43166 | K40: =((10*G40-F40)/F40)*100 -> 370.86331
...

Sheet Summary
A1: Country | B1: Occupation | C1: Basic Payback - Median (yrs) | D1: Basic Payback - IQR Low (yrs) | E1: Basic Payback - IQR High (yrs) | F1: Realistic Payback - Median (yrs) | G1: Realistic Payback - IQR Low (yrs) | H1: Realistic Payback - IQR High (yrs) | I1: 5yr ROI - Median (%) | J1: 5yr ROI - IQR Low (%) | K1: 5yr ROI - IQR High (%) | L1: 10yr ROI - Median (%) | M1: 10yr ROI - IQR Low (%) | N1: 10yr ROI - IQR High (%)
A2: United States | B2: Data analyst | C2: {=MEDIAN(IF(((ROI_Calculations!$A$2:$A$121=A2)*(ROI_Calculations!$D$2:$D$121=B2)),ROI_Calculations!$H$2:$H$121))} -> 1.4404447 | D2: {=PERCENTILE(IF(((ROI_Calculations!$A$2:$A$121=A2)*(ROI_Calculations!$D$2:$D$121=B2)),ROI_Calculations!$H$2:$H$121),0.25)} -> 1.3165961 | E2: {=PERCENTILE(IF(((ROI_Calculations!$A$2:$A$121=A2)*(ROI_Calculations!$D$2:$D$121=B2)),ROI_Calculations!$H$2:$H$121),0.75)} -> 1.6715281 | F2: {=MEDIAN(IF(((ROI_Calculations!$A$2:$A$121=A2)*(ROI_Calculations!$D$2:$D$121=B2)),ROI_Calculations!$I$2:$I$121))} -> 2.5377537 | G2: {=PERCENTILE(IF(((ROI_Calculations!$A$2:$A$121=A2)*(ROI_Calculations!$D$2:$D$121=B2)),ROI_Calculations!$I$2:$I$121),0.25)} -> 2.2208047 | H2: {=PERCENTILE(IF(((ROI_Calculations!$A$2:$A$121=A2)*(ROI_Calculations!$D$2:$D$121=B2)),ROI_Calculations!$I$2:$I$121),0.75)} -> 2.6821158 | I2: {=MEDIAN(IF(((ROI_Calculations!$A$2:$A$121=A2)*(ROI_Calculations!$D$2:$D$121=B2)),ROI_Calculations!$J$2:$J$121))} -> 97.518267 | J2: {=PERCENTILE(IF(((ROI_Calculations!$A$2:$A$121=A2)*(ROI_Calculations!$D$2:$D$121=B2)),ROI_Calculations!$J$2:$J$121),0.25)} -> 86.420113 | K2: {=PERCENTILE(IF(((ROI_Calculations!$A$2:$A$121=A2)*(ROI_Calculations!$D$2:$D$121=B2)),ROI_Calculations!$J$2:$J$121),0.75)} -> 125.4982 | L2: {=MEDIAN(IF(((ROI_Calculations!$A$2:$A$121=A2)*(ROI_Calculations!$D$2:$D$121=B2)),ROI_Calculations!$K$2:$K$121))} -> 295.03653 | M2: {=PERCENTILE(IF(((ROI_Calculations!$A$2:$A$121=A2)*(ROI_Calculations!$D$2:$D$121=B2)),ROI_Calculations!$K$2:$K$121),0.25)} -> 272.84023 | N2: {=PERCENTILE(IF(((ROI_Calculations!$A$2:$A$121=A2)*(ROI_Calculations!$D$2:$D$121=B2)),ROI_Calculations!$K$2:$K$121),0.75)} -> 350.99639
A3: United States | B3: Data scientist | C3: {=MEDIAN(IF(((ROI_Calculations!$A$2:$A$121=A3)*(ROI_Calculations!$D$2:$D$121=B3)),ROI_Calculations!$H$2:$H$121))} -> 1.1867413 | D3: {=PERCENTILE(IF(((ROI_Calculations!$A$2:$A$121=A3)*(ROI_Calculations!$D$2:$D$121=B3)),ROI_Calculations!$H$2:$H$121),0.25)} -> 1.084706 | E3: {=PERCENTILE(IF(((ROI_Calculations!$A$2:$A$121=A3)*(ROI_Calculations!$D$2:$D$121=B3)),ROI_Calculations!$H$2:$H$121),0.75)} -> 1.3771244 | F3: {=MEDIAN(IF(((ROI_Calculations!$A$2:$A$121=A3)*(ROI_Calculations!$D$2:$D$121=B3)),ROI_Calculations!$I$2:$I$121))} -> 2.0907829 | G3: {=PERCENTILE(IF(((ROI_Calculations!$A$2:$A$121=A3)*(ROI_Calculations!$D$2:$D$121=B3)),ROI_Calculations!$I$2:$I$121),0.25)} -> 1.8296576 | H3: {=PERCENTILE(IF(((ROI_Calculations!$A$2:$A$121=A3)*(ROI_Calculations!$D$2:$D$121=B3)),ROI_Calculations!$I$2:$I$121),0.75)} -> 2.2097187 | I3: {=MEDIAN(IF(((ROI_Calculations!$A$2:$A$121=A3)*(ROI_Calculations!$D$2:$D$121=B3)),ROI_Calculations!$J$2:$J$121))} -> 139.74403 | J3: {=PERCENTILE(IF(((ROI_Calculations!$A$2:$A$121=A3)*(ROI_Calculations!$D$2:$D$121=B3)),ROI_Calculations!$J$2:$J$121),0.25)} -> 126.27329 | K3: {=PERCENTILE(IF(((ROI_Calculations!$A$2:$A$121=A3)*(ROI_Calculations!$D$2:$D$121=B3)),ROI_Calculations!$J$2:$J$121),0.75)} -> 173.70555 | L3: {=MEDIAN(IF(((ROI_Calculations!$A$2:$A$121=A3)*(ROI_Calculations!$D$2:$D$121=B3)),ROI_Calculations!$K$2:$K$121))} -> 379.48805 | M3: {=PERCENTILE(IF(((ROI_Calculations!$A$2:$A$121=A3)*(ROI_Calculations!$D$2:$D$121=B3)),ROI_Calculations!$K$2:$K$121),0.25)} -> 352.54658 | N3: {=PERCENTILE(IF(((ROI_Calculations!$A$2:$A$121=A3)*(ROI_Calculations!$D$2:$D$121=B3)),ROI_Calculations!$K$2:$K$121),0.75)} -> 447.41109
A4: United Kingdom | B4: Data analyst | C4: {=MEDIAN(IF(((ROI_Calculations!$A$2:$A$121=A4)*(ROI_Calculations!$D$2:$D$121=B4)),ROI_Calculations!$H$2:$H$121))} -> 1.6337361 | D4: {=PERCENTILE(IF(((ROI_Calculations!$A$2:$A$121=A4)*(ROI_Calculations!$D$2:$D$121=B4)),ROI_Calculations!$H$2:$H$121),0.25)} -> 1.5530163 | E4: {=PERCENTILE(IF(((ROI_Calculations!$A$2:$A$121=A4)*(ROI_Calculations!$D$2:$D$121=B4)),ROI_Calculations!$H$2:$H$121),0.75)} -> 1.6700566 | F4: {=MEDIAN(IF(((ROI_Calculations!$A$2:$A$121=A4)*(ROI_Calculations!$D$2:$D$121=B4)),ROI_Calculations!$I$2:$I$121))} -> 2.4526335 | G4: {=PERCENTILE(IF(((ROI_Calculations!$A$2:$A$121=A4)*(ROI_Calculations!$D$2:$D$121=B4)),ROI_Calculations!$I$2:$I$121),0.25)} -> 2.342842 | H4: {=PERCENTILE(IF(((ROI_Calculations!$A$2:$A$121=A4)*(ROI_Calculations!$D$2:$D$121=B4)),ROI_Calculations!$I$2:$I$121),0.75)} -> 2.5530548 | I4: {=MEDIAN(IF(((ROI_Calculations!$A$2:$A$121=A4)*(ROI_Calculations!$D$2:$D$121=B4)),ROI_Calculations!$J$2:$J$121))} -> 103.86696 | J4: {=PERCENTILE(IF(((ROI_Calculations!$A$2:$A$121=A4)*(ROI_Calculations!$D$2:$D$121=B4)),ROI_Calculations!$J$2:$J$121),0.25)} -> 95.845771 | K4: {=PERCENTILE(IF(((ROI_Calculations!$A$2:$A$121=A4)*(ROI_Calculations!$D$2:$D$121=B4)),ROI_Calculations!$J$2:$J$121),0.75)} -> 113.50587 | L4: {=MEDIAN(IF(((ROI_Calculations!$A$2:$A$121=A4)*(ROI_Calculations!$D$2:$D$121=B4)),ROI_Calculations!$K$2:$K$121))} -> 307.73391 | M4: {=PERCENTILE(IF(((ROI_Calculations!$A$2:$A$121=A4)*(ROI_Calculations!$D$2:$D$121=B4)),ROI_Calculations!$K$2:$K$121),0.25)} -> 291.69154 | N4: {=PERCENTILE(IF(((ROI_Calculations!$A$2:$A$121=A4)*(ROI_Calculations!$D$2:$D$121=B4)),ROI_Calculations!$K$2:$K$121),0.75)} -> 327.01174
A5: United Kingdom | B5: Data scientist | C5: {=MEDIAN(IF(((ROI_Calculations!$A$2:$A$121=A5)*(ROI_Calculations!$D$2:$D$121=B5)),ROI_Calculations!$H$2:$H$121))} -> 1.2007955 | D5: {=PERCENTILE(IF(((ROI_Calculations!$A$2:$A$121=A5)*(ROI_Calculations!$D$2:$D$121=B5)),ROI_Calculations!$H$2:$H$121),0.25)} -> 1.1414665 | E5: {=PERCENTILE(IF(((ROI_Calculations!$A$2:$A$121=A5)*(ROI_Calculations!$D$2:$D$121=B5)),ROI_Calculations!$H$2:$H$121),0.75)} -> 1.227491 | F5: {=MEDIAN(IF(((ROI_Calculations!$A$2:$A$121=A5)*(ROI_Calculations!$D$2:$D$121=B5)),ROI_Calculations!$I$2:$I$121))} -> 1.8026848 | G5: {=PERCENTILE(IF(((ROI_Calculations!$A$2:$A$121=A5)*(ROI_Calculations!$D$2:$D$121=B5)),ROI_Calculations!$I$2:$I$121),0.25)} -> 1.7219881 | H5: {=PERCENTILE(IF(((ROI_Calculations!$A$2:$A$121=A5)*(ROI_Calculations!$D$2:$D$121=B5)),ROI_Calculations!$I$2:$I$121),0.75)} -> 1.8764944 | I5: {=MEDIAN(IF(((ROI_Calculations!$A$2:$A$121=A5)*(ROI_Calculations!$D$2:$D$121=B5)),ROI_Calculations!$J$2:$J$121))} -> 177.37014 | J5: {=PERCENTILE(IF(((ROI_Calculations!$A$2:$A$121=A5)*(ROI_Calculations!$D$2:$D$121=B5)),ROI_Calculations!$J$2:$J$121),0.25)} -> 166.45695 | K5: {=PERCENTILE(IF(((ROI_Calculations!$A$2:$A$121=A5)*(ROI_Calculations!$D$2:$D$121=B5)),ROI_Calculations!$J$2:$J$121),0.75)} -> 190.48431 | L5: {=MEDIAN(IF(((ROI_Calculations!$A$2:$A$121=A5)*(ROI_Calculations!$D$2:$D$121=B5)),ROI_Calculations!$K$2:$K$121))} -> 454.74028 | M5: {=PERCENTILE(IF(((ROI_Calculations!$A$2:$A$121=A5)*(ROI_Calculations!$D$2:$D$121=B5)),ROI_Calculations!$K$2:$K$121),0.25)} -> 432.91391 | N5: {=PERCENTILE(IF(((ROI_Calculations!$A$2:$A$121=A5)*(ROI_Calculations!$D$2:$D$121=B5)),ROI_Calculations!$K$2:$K$121),0.75)} -> 480.96863
A6: Canada | B6: Data analyst | C6: {=MEDIAN(IF(((ROI_Calculations!$A$2:$A$121=A6)*(ROI_Calculations!$D$2:$D$121=B6)),ROI_Calculations!$H$2:$H$121))} -> 0.99723616 | D6: {=PERCENTILE(IF(((ROI_Calculations!$A$2:$A$121=A6)*(ROI_Calculations!$D$2:$D$121=B6)),ROI_Calculations!$H$2:$H$121),0.25)} -> 0.94395671 | E6: {=PERCENTILE(IF(((ROI_Calculations!$A$2:$A$121=A6)*(ROI_Calculations!$D$2:$D$121=B6)),ROI_Calculations!$H$2:$H$121),0.75)} -> 1.282539 | F6: {=MEDIAN(IF(((ROI_Calculations!$A$2:$A$121=A6)*(ROI_Calculations!$D$2:$D$121=B6)),ROI_Calculations!$I$2:$I$121))} -> 1.613875 | G6: {=PERCENTILE(IF(((ROI_Calculations!$A$2:$A$121=A6)*(ROI_Calculations!$D$2:$D$121=B6)),ROI_Calculations!$I$2:$I$121),0.25)} -> 1.4392477 | H6: {=PERCENTILE(IF(((ROI_Calculations!$A$2:$A$121=A6)*(ROI_Calculations!$D$2:$D$121=B6)),ROI_Calculations!$I$2:$I$121),0.75)} -> 1.7372782 | I6: {=MEDIAN(IF(((ROI_Calculations!$A$2:$A$121=A6)*(ROI_Calculations!$D$2:$D$121=B6)),ROI_Calculations!$J$2:$J$121))} -> 209.96639 | J6: {=PERCENTILE(IF(((ROI_Calculations!$A$2:$A$121=A6)*(ROI_Calculations!$D$2:$D$121=B6)),ROI_Calculations!$J$2:$J$121),0.25)} -> 187.8493 | K6: {=PERCENTILE(IF(((ROI_Calculations!$A$2:$A$121=A6)*(ROI_Calculations!$D$2:$D$121=B6)),ROI_Calculations!$J$2:$J$121),0.75)} -> 247.58862 | L6: {=MEDIAN(IF(((ROI_Calculations!$A$2:$A$121=A6)*(ROI_Calculations!$D$2:$D$121=B6)),ROI_Calculations!$K$2:$K$121))} -> 519.93277 | M6: {=PERCENTILE(IF(((ROI_Calculations!$A$2:$A$121=A6)*(ROI_Calculations!$D$2:$D$121=B6)),ROI_Calculations!$K$2:$K$121),0.25)} -> 475.6986 | N6: {=PERCENTILE(IF(((ROI_Calculations!$A$2:$A$121=A6)*(ROI_Calculations!$D$2:$D$121=B6)),ROI_Calculations!$K$2:$K$121),0.75)} -> 595.17724
A7: Canada | B7: Data scientist | C7: {=MEDIAN(IF(((ROI_Calculations!$A$2:$A$121=A7)*(ROI_Calculations!$D$2:$D$121=B7)),ROI_Calculations!$H$2:$H$121))} -> 0.84428583 | D7: {=PERCENTILE(IF(((ROI_Calculations!$A$2:$A$121=A7)*(ROI_Calculations!$D$2:$D$121=B7)),ROI_Calculations!$H$2:$H$121),0.25)} -> 0.79917807 | E7: {=PERCENTILE(IF(((ROI_Calculations!$A$2:$A$121=A7)*(ROI_Calculations!$D$2:$D$121=B7)),ROI_Calculations!$H$2:$H$121),0.75)} -> 1.0858306 | F7: {=MEDIAN(IF(((ROI_Calculations!$A$2:$A$121=A7)*(ROI_Calculations!$D$2:$D$121=B7)),ROI_Calculations!$I$2:$I$121))} -> 1.3663481 | G7: {=PERCENTILE(IF(((ROI_Calculations!$A$2:$A$121=A7)*(ROI_Calculations!$D$2:$D$121=B7)),ROI_Calculations!$I$2:$I$121),0.25)} -> 1.2185042 | H7: {=PERCENTILE(IF(((ROI_Calculations!$A$2:$A$121=A7)*(ROI_Calculations!$D$2:$D$121=B7)),ROI_Calculations!$I$2:$I$121),0.75)} -> 1.4708245 | I7: {=MEDIAN(IF(((ROI_Calculations!$A$2:$A$121=A7)*(ROI_Calculations!$D$2:$D$121=B7)),ROI_Calculations!$J$2:$J$121))} -> 266.11972 | J7: {=PERCENTILE(IF(((ROI_Calculations!$A$2:$A$121=A7)*(ROI_Calculations!$D$2:$D$121=B7)),ROI_Calculations!$J$2:$J$121),0.25)} -> 239.99591 | K7: {=PERCENTILE(IF(((ROI_Calculations!$A$2:$A$121=A7)*(ROI_Calculations!$D$2:$D$121=B7)),ROI_Calculations!$J$2:$J$121),0.75)} -> 310.55757 | L7: {=MEDIAN(IF(((ROI_Calculations!$A$2:$A$121=A7)*(ROI_Calculations!$D$2:$D$121=B7)),ROI_Calculations!$K$2:$K$121))} -> 632.23943 | M7: {=PERCENTILE(IF(((ROI_Calculations!$A$2:$A$121=A7)*(ROI_Calculations!$D$2:$D$121=B7)),ROI_Calculations!$K$2:$K$121),0.25)} -> 579.99182 | N7: {=PERCENTILE(IF(((ROI_Calculations!$A$2:$A$121=A7)*(ROI_Calculations!$D$2:$D$121=B7)),ROI_Calculations!$K$2:$K$121),0.75)} -> 721.11514
A8: Australia | B8: Data analyst | C8: {=MEDIAN(IF(((ROI_Calculations!$A$2:$A$121=A8)*(ROI_Calculations!$D$2:$D$121=B8)),ROI_Calculations!$H$2:$H$121))} -> 1.7038627 | D8: {=PERCENTILE(IF(((ROI_Calculations!$A$2:$A$121=A8)*(ROI_Calculations!$D$2:$D$121=B8)),ROI_Calculations!$H$2:$H$121),0.25)} -> 1.4757566 | E8: {=PERCENTILE(IF(((ROI_Calculations!$A$2:$A$121=A8)*(ROI_Calculations!$D$2:$D$121=B8)),ROI_Calculations!$H$2:$H$121),0.75)} -> 1.8392154 | F8: {=MEDIAN(IF(((ROI_Calculations!$A$2:$A$121=A8)*(ROI_Calculations!$D$2:$D$121=B8)),ROI_Calculations!$I$2:$I$121))} -> 2.862826 | G8: {=PERCENTILE(IF(((ROI_Calculations!$A$2:$A$121=A8)*(ROI_Calculations!$D$2:$D$121=B8)),ROI_Calculations!$I$2:$I$121),0.25)} -> 2.6377902 | H8: {=PERCENTILE(IF(((ROI_Calculations!$A$2:$A$121=A8)*(ROI_Calculations!$D$2:$D$121=B8)),ROI_Calculations!$I$2:$I$121),0.75)} -> 2.9946132 | I8: {=MEDIAN(IF(((ROI_Calculations!$A$2:$A$121=A8)*(ROI_Calculations!$D$2:$D$121=B8)),ROI_Calculations!$J$2:$J$121))} -> 74.6541 | J8: {=PERCENTILE(IF(((ROI_Calculations!$A$2:$A$121=A8)*(ROI_Calculations!$D$2:$D$121=B8)),ROI_Calculations!$J$2:$J$121),0.25)} -> 67.017916 | K8: {=PERCENTILE(IF(((ROI_Calculations!$A$2:$A$121=A8)*(ROI_Calculations!$D$2:$D$121=B8)),ROI_Calculations!$J$2:$J$121),0.75)} -> 89.562144 | L8: {=MEDIAN(IF(((ROI_Calculations!$A$2:$A$121=A8)*(ROI_Calculations!$D$2:$D$121=B8)),ROI_Calculations!$K$2:$K$121))} -> 249.3082 | M8: {=PERCENTILE(IF(((ROI_Calculations!$A$2:$A$121=A8)*(ROI_Calculations!$D$2:$D$121=B8)),ROI_Calculations!$K$2:$K$121),0.25)} -> 234.03583 | N8: {=PERCENTILE(IF(((ROI_Calculations!$A$2:$A$121=A8)*(ROI_Calculations!$D$2:$D$121=B8)),ROI_Calculations!$K$2:$K$121),0.75)} -> 279.12429
A9: Australia | B9: Data scientist | C9: {=MEDIAN(IF(((ROI_Calculations!$A$2:$A$121=A9)*(ROI_Calculations!$D$2:$D$121=B9)),ROI_Calculations!$H$2:$H$121))} -> 1.5709213 | D9: {=PERCENTILE(IF(((ROI_Calculations!$A$2:$A$121=A9)*(ROI_Calculations!$D$2:$D$121=B9)),ROI_Calculations!$H$2:$H$121),0.25)} -> 1.3606128 | E9: {=PERCENTILE(IF(((ROI_Calculations!$A$2:$A$121=A9)*(ROI_Calculations!$D$2:$D$121=B9)),ROI_Calculations!$H$2:$H$121),0.75)} -> 1.6957133 | F9: {=MEDIAN(IF(((ROI_Calculations!$A$2:$A$121=A9)*(ROI_Calculations!$D$2:$D$121=B9)),ROI_Calculations!$I$2:$I$121))} -> 2.6394582 | G9: {=PERCENTILE(IF(((ROI_Calculations!$A$2:$A$121=A9)*(ROI_Calculations!$D$2:$D$121=B9)),ROI_Calculations!$I$2:$I$121),0.25)} -> 2.4319805 | H9: {=PERCENTILE(IF(((ROI_Calculations!$A$2:$A$121=A9)*(ROI_Calculations!$D$2:$D$121=B9)),ROI_Calculations!$I$2:$I$121),0.75)} -> 2.7609629 | I9: {=MEDIAN(IF(((ROI_Calculations!$A$2:$A$121=A9)*(ROI_Calculations!$D$2:$D$121=B9)),ROI_Calculations!$J$2:$J$121))} -> 89.434446 | J9: {=PERCENTILE(IF(((ROI_Calculations!$A$2:$A$121=A9)*(ROI_Calculations!$D$2:$D$121=B9)),ROI_Calculations!$J$2:$J$121),0.25)} -> 81.152039 | K9: {=PERCENTILE(IF(((ROI_Calculations!$A$2:$A$121=A9)*(ROI_Calculations!$D$2:$D$121=B9)),ROI_Calculations!$J$2:$J$121),0.75)} -> 105.6041 | L9: {=MEDIAN(IF(((ROI_Calculations!$A$2:$A$121=A9)*(ROI_Calculations!$D$2:$D$121=B9)),ROI_Calculations!$K$2:$K$121))} -> 278.86889 | M9: {=PERCENTILE(IF(((ROI_Calculations!$A$2:$A$121=A9)*(ROI_Calculations!$D$2:$D$121=B9)),ROI_Calculations!$K$2:$K$121),0.25)} -> 262.30408 | N9: {=PERCENTILE(IF(((ROI_Calculations!$A$2:$A$121=A9)*(ROI_Calculations!$D$2:$D$121=B9)),ROI_Calculations!$K$2:$K$121),0.75)} -> 311.20821
A10: Germany | B10: Data analyst | C10: {=MEDIAN(IF(((ROI_Calculations!$A$2:$A$121=A10)*(ROI_Calculations!$D$2:$D$121=B10)),ROI_Calculations!$H$2:$H$121))} -> 0 | D10: {=PERCENTILE(IF(((ROI_Calculations!$A$2:$A$121=A10)*(ROI_Calculations!$D$2:$D$121=B10)),ROI_Calculations!$H$2:$H$121),0.25)} -> 0 | E10: {=PERCENTILE(IF(((ROI_Calculations!$A$2:$A$121=A10)*(ROI_Calculations!$D$2:$D$121=B10)),ROI_Calculations!$H$2:$H$121),0.75)} -> 0.12358623 | F10: {=MEDIAN(IF(((ROI_Calculations!$A$2:$A$121=A10)*(ROI_Calculations!$D$2:$D$121=B10)),ROI_Calculations!$I$2:$I$121))} -> 0.7250826 | G10: {=PERCENTILE(IF(((ROI_Calculations!$A$2:$A$121=A10)*(ROI_Calculations!$D$2:$D$121=B10)),ROI_Calculations!$I$2:$I$121),0.25)} -> 0.66344925 | H10: {=PERCENTILE(IF(((ROI_Calculations!$A$2:$A$121=A10)*(ROI_Calculations!$D$2:$D$121=B10)),ROI_Calculations!$I$2:$I$121),0.75)} -> 0.846203 | I10: {=MEDIAN(IF(((ROI_Calculations!$A$2:$A$121=A10)*(ROI_Calculations!$D$2:$D$121=B10)),ROI_Calculations!$J$2:$J$121))} -> 589.57661 | J10: {=PERCENTILE(IF(((ROI_Calculations!$A$2:$A$121=A10)*(ROI_Calculations!$D$2:$D$121=B10)),ROI_Calculations!$J$2:$J$121),0.25)} -> 491.01335 | K10: {=PERCENTILE(IF(((ROI_Calculations!$A$2:$A$121=A10)*(ROI_Calculations!$D$2:$D$121=B10)),ROI_Calculations!$J$2:$J$121),0.75)} -> 654.09332 | L10: {=MEDIAN(IF(((ROI_Calculations!$A$2:$A$121=A10)*(ROI_Calculations!$D$2:$D$121=B10)),ROI_Calculations!$K$2:$K$121))} -> 1279.1532 | M10: {=PERCENTILE(IF(((ROI_Calculations!$A$2:$A$121=A10)*(ROI_Calculations!$D$2:$D$121=B10)),ROI_Calculations!$K$2:$K$121),0.25)} -> 1082.0267 | N10: {=PERCENTILE(IF(((ROI_Calculations!$A$2:$A$121=A10)*(ROI_Calculations!$D$2:$D$121=B10)),ROI_Calculations!$K$2:$K$121),0.75)} -> 1408.1866
A11: Germany | B11: Data scientist | C11: {=MEDIAN(IF(((ROI_Calculations!$A$2:$A$121=A11)*(ROI_Calculations!$D$2:$D$121=B11)),ROI_Calculations!$H$2:$H$121))} -> 0 | D11: {=PERCENTILE(IF(((ROI_Calculations!$A$2:$A$121=A11)*(ROI_Calculations!$D$2:$D$121=B11)),ROI_Calculations!$H$2:$H$121),0.25)} -> 0 | E11: {=PERCENTILE(IF(((ROI_Calculations!$A$2:$A$121=A11)*(ROI_Calculations!$D$2:$D$121=B11)),ROI_Calculations!$H$2:$H$121),0.75)} -> 0.11066184 | F11: {=MEDIAN(IF(((ROI_Calculations!$A$2:$A$121=A11)*(ROI_Calculations!$D$2:$D$121=B11)),ROI_Calculations!$I$2:$I$121))} -> 0.64925502 | G11: {=PERCENTILE(IF(((ROI_Calculations!$A$2:$A$121=A11)*(ROI_Calculations!$D$2:$D$121=B11)),ROI_Calculations!$I$2:$I$121),0.25)} -> 0.59406716 | H11: {=PERCENTILE(IF(((ROI_Calculations!$A$2:$A$121=A11)*(ROI_Calculations!$D$2:$D$121=B11)),ROI_Calculations!$I$2:$I$121),0.75)} -> 0.75770892 | I11: {=MEDIAN(IF(((ROI_Calculations!$A$2:$A$121=A11)*(ROI_Calculations!$D$2:$D$121=B11)),ROI_Calculations!$J$2:$J$121))} -> 670.11341 | J11: {=PERCENTILE(IF(((ROI_Calculations!$A$2:$A$121=A11)*(ROI_Calculations!$D$2:$D$121=B11)),ROI_Calculations!$J$2:$J$121),0.25)} -> 560.03879 | K11: {=PERCENTILE(IF(((ROI_Calculations!$A$2:$A$121=A11)*(ROI_Calculations!$D$2:$D$121=B11)),ROI_Calculations!$J$2:$J$121),0.75)} -> 742.16514 | L11: {=MEDIAN(IF(((ROI_Calculations!$A$2:$A$121=A11)*(ROI_Calculations!$D$2:$D$121=B11)),ROI_Calculations!$K$2:$K$121))} -> 1440.2268 | M11: {=PERCENTILE(IF(((ROI_Calculations!$A$2:$A$121=A11)*(ROI_Calculations!$D$2:$D$121=B11)),ROI_Calculations!$K$2:$K$121),0.25)} -> 1220.0776 | N11: {=PERCENTILE(IF(((ROI_Calculations!$A$2:$A$121=A11)*(ROI_Calculations!$D$2:$D$121=B11)),ROI_Calculations!$K$2:$K$121),0.75)} -> 1584.3303
A12: Netherlands | B12: Data analyst | C12: {=MEDIAN(IF(((ROI_Calculations!$A$2:$A$121=A12)*(ROI_Calculations!$D$2:$D$121=B12)),ROI_Calculations!$H$2:$H$121))} -> 1.1805107 | D12: {=PERCENTILE(IF(((ROI_Calculations!$A$2:$A$121=A12)*(ROI_Calculations!$D$2:$D$121=B12)),ROI_Calculations!$H$2:$H$121),0.25)} -> 0.8056922 | E12: {=PERCENTILE(IF(((ROI_Calculations!$A$2:$A$121=A12)*(ROI_Calculations!$D$2:$D$121=B12)),ROI_Calculations!$H$2:$H$121),0.75)} -> 1.2665613 | F12: {=MEDIAN(IF(((ROI_Calculations!$A$2:$A$121=A12)*(ROI_Calculations!$D$2:$D$121=B12)),ROI_Calculations!$I$2:$I$121))} -> 1.9430897 | G12: {=PERCENTILE(IF(((ROI_Calculations!$A$2:$A$121=A12)*(ROI_Calculations!$D$2:$D$121=B12)),ROI_Calculations!$I$2:$I$121),0.25)} -> 1.2932303 | H12: {=PERCENTILE(IF(((ROI_Calculations!$A$2:$A$121=A12)*(ROI_Calculations!$D$2:$D$121=B12)),ROI_Calculations!$I$2:$I$121),0.75)} -> 2.0859276 | I12: {=MEDIAN(IF(((ROI_Calculations!$A$2:$A$121=A12)*(ROI_Calculations!$D$2:$D$121=B12)),ROI_Calculations!$J$2:$J$121))} -> 157.42196 | J12: {=PERCENTILE(IF(((ROI_Calculations!$A$2:$A$121=A12)*(ROI_Calculations!$D$2:$D$121=B12)),ROI_Calculations!$J$2:$J$121),0.25)} -> 139.85019 | K12: {=PERCENTILE(IF(((ROI_Calculations!$A$2:$A$121=A12)*(ROI_Calculations!$D$2:$D$121=B12)),ROI_Calculations!$J$2:$J$121),0.75)} -> 300.84608 | L12: {=MEDIAN(IF(((ROI_Calculations!$A$2:$A$121=A12)*(ROI_Calculations!$D$2:$D$121=B12)),ROI_Calculations!$K$2:$K$121))} -> 414.84393 | M12: {=PERCENTILE(IF(((ROI_Calculations!$A$2:$A$121=A12)*(ROI_Calculations!$D$2:$D$121=B12)),ROI_Calculations!$K$2:$K$121),0.25)} -> 379.70037 | N12: {=PERCENTILE(IF(((ROI_Calculations!$A$2:$A$121=A12)*(ROI_Calculations!$D$2:$D$121=B12)),ROI_Calculations!$K$2:$K$121),0.75)} -> 701.69217
A13: Netherlands | B13: Data scientist | C13: {=MEDIAN(IF(((ROI_Calculations!$A$2:$A$121=A13)*(ROI_Calculations!$D$2:$D$121=B13)),ROI_Calculations!$H$2:$H$121))} -> 1.0015103 | D13: {=PERCENTILE(IF(((ROI_Calculations!$A$2:$A$121=A13)*(ROI_Calculations!$D$2:$D$121=B13)),ROI_Calculations!$H$2:$H$121),0.25)} -> 0.68352544 | E13: {=PERCENTILE(IF(((ROI_Calculations!$A$2:$A$121=A13)*(ROI_Calculations!$D$2:$D$121=B13)),ROI_Calculations!$H$2:$H$121),0.75)} -> 1.0745131 | F13: {=MEDIAN(IF(((ROI_Calculations!$A$2:$A$121=A13)*(ROI_Calculations!$D$2:$D$121=B13)),ROI_Calculations!$I$2:$I$121))} -> 1.6484599 | G13: {=PERCENTILE(IF(((ROI_Calculations!$A$2:$A$121=A13)*(ROI_Calculations!$D$2:$D$121=B13)),ROI_Calculations!$I$2:$I$121),0.25)} -> 1.0971383 | H13: {=PERCENTILE(IF(((ROI_Calculations!$A$2:$A$121=A13)*(ROI_Calculations!$D$2:$D$121=B13)),ROI_Calculations!$I$2:$I$121),0.75)} -> 1.7696393 | I13: {=MEDIAN(IF(((ROI_Calculations!$A$2:$A$121=A13)*(ROI_Calculations!$D$2:$D$121=B13)),ROI_Calculations!$J$2:$J$121))} -> 203.43109 | J13: {=PERCENTILE(IF(((ROI_Calculations!$A$2:$A$121=A13)*(ROI_Calculations!$D$2:$D$121=B13)),ROI_Calculations!$J$2:$J$121),0.25)} -> 182.7187 | K13: {=PERCENTILE(IF(((ROI_Calculations!$A$2:$A$121=A13)*(ROI_Calculations!$D$2:$D$121=B13)),ROI_Calculations!$J$2:$J$121),0.75)} -> 372.48946 | L13: {=MEDIAN(IF(((ROI_Calculations!$A$2:$A$121=A13)*(ROI_Calculations!$D$2:$D$121=B13)),ROI_Calculations!$K$2:$K$121))} -> 506.86218 | M13: {=PERCENTILE(IF(((ROI_Calculations!$A$2:$A$121=A13)*(ROI_Calculations!$D$2:$D$121=B13)),ROI_Calculations!$K$2:$K$121),0.25)} -> 465.4374 | N13: {=PERCENTILE(IF(((ROI_Calculations!$A$2:$A$121=A13)*(ROI_Calculations!$D$2:$D$121=B13)),ROI_Calculations!$K$2:$K$121),0.75)} -> 844.97891
